<?xml version="1.0" ?>
<!-- =================================================================================== -->
<!-- |    This document was autogenerated by xacro from /home/abhyudit/ocs2_ws/src/ros_kortex/kortex_description/robots/gen3_robotiq_2f_85.xacro | -->
<!-- |    EDITING THIS FILE BY HAND IS NOT RECOMMENDED                                 | -->
<!-- =================================================================================== -->
<robot name="gen3_robotiq_2f_85_mobile_base">
  <!-- Mobile Base -->
  <!-- Add joint friction? -->
  <material name="white">
    <color rgba="0.7 0.7 0.7 1"/>
  </material>
  <material name="black">
    <color rgba="0.2 0.2 0.2 1"/>
  </material>
  <link name="mobile_base_link">
  </link>
  <link name="mabi_attachment">
  </link>
  <joint name="base_link_to_mabi_attachment" type="fixed">
    <parent link="mobile_base_link"/>
    <child link="mabi_attachment"/>
    <origin xyz="0 0 -0.0"/>
  </joint>
  <link name="body">
    <visual>
      <origin rpy="0 0 0" xyz="0 0 0"/>
      <geometry>
        <mesh filename="package://ocs2_robotic_assets/resources/mobile_manipulator/kortex/meshes/body.stl" scale="0.001 0.001 0.001"/>
      </geometry>
      <material name="white"/>
    </visual>
    <collision>
      <geometry>
        <box size="0.902 0.800 0.280"/>
      </geometry>
    </collision>
    <inertial>
      <mass value="31.90123643"/>
      <origin xyz="0.000000562323 0 -0.003378692933"/>
      <inertia ixx="3.238567971" ixy="-0.0001169154562" ixz="-0.000000014560378" iyy="3.455603445" iyz="0.0005658238908" izz="6.052079931"/>
    </inertial>
  </link>
  <joint name="base_link_to_body" type="fixed">
    <parent link="mobile_base_link"/>
    <child link="body"/>
    <origin xyz="0 0 -0.140"/>
  </joint>
  <link name="arm_rl">
    <visual>
      <origin rpy="3.141592653589793 0 4.71238898038469" xyz="0 0 0"/>
      <geometry>
        <mesh filename="package://ocs2_robotic_assets/resources/mobile_manipulator/kortex/meshes/arm_rl.stl" scale="0.001 0.001 0.001"/>
      </geometry>
      <material name="white"/>
    </visual>
    <collision>
      <origin rpy="3.141592653589793 0 4.71238898038469" xyz="0.0 0.232 0.130"/>
      <geometry>
        <box size="0.464 0.090 0.280"/>
      </geometry>
    </collision>
    <inertial>
      <mass value="4.680353119"/>
      <origin xyz="-0.2874248231 -0.000025732551 -0.1327515781"/>
      <inertia ixx="0.03793414031" ixy="0.000004904354526" ixz="-0.003907344591" iyy="0.1401583096" iyz="-0.00001817130601" izz="0.1060310134"/>
    </inertial>
  </link>
  <joint name="left_back_brake_joint" type="fixed">
    <parent link="body"/>
    <child link="arm_rl"/>
    <origin rpy="3.141592653589793 0 4.71238898038469" xyz="-0.4031 0.353 0.1295"/>
  </joint>
  <link name="arm_rr">
    <visual>
      <origin rpy="3.141592653589793 0 1.5707963267948966" xyz="0 0 0"/>
      <geometry>
        <mesh filename="package://ocs2_robotic_assets/resources/mobile_manipulator/kortex/meshes/arm_rr.stl" scale="0.001 0.001 0.001"/>
      </geometry>
      <material name="white"/>
    </visual>
    <collision>
      <origin rpy="3.141592653589793 0 1.5707963267948966" xyz="0.0 -0.232 0.130"/>
      <geometry>
        <box size="0.464 0.090 0.280"/>
      </geometry>
    </collision>
    <inertial>
      <mass value="4.680353119"/>
      <origin xyz="-0.2874248231 0.000025732551 -0.1327515781"/>
      <inertia ixx="0.03793414031" ixy="-0.000004904354526" ixz="-0.003907344591" iyy="0.1401583096" iyz="-0.00001817130601" izz="0.1060310134"/>
    </inertial>
  </link>
  <joint name="right_back_brake_joint" type="fixed">
    <parent link="body"/>
    <child link="arm_rr"/>
    <origin rpy="3.141592653589793 0 1.5707963267948966" xyz="-0.4031 -0.353 0.1290"/>
  </joint>
  <link name="arm_fl">
    <visual>
      <origin rpy="3.141592653589793 0 4.71238898038469" xyz="0 0 0"/>
      <geometry>
        <mesh filename="package://ocs2_robotic_assets/resources/mobile_manipulator/kortex/meshes/arm_fl.stl" scale="0.001 0.001 0.001"/>
      </geometry>
      <material name="white"/>
    </visual>
    <collision>
      <origin rpy="3.141592653589793 0 4.71238898038469" xyz="0.0 -0.232 0.130"/>
      <geometry>
        <box size="0.464 0.090 0.280"/>
      </geometry>
    </collision>
    <inertial>
      <mass value="4.680353119"/>
      <origin xyz="0.2874248231 -0.000025732551 -0.1327515781"/>
      <inertia ixx="0.03793414031" ixy="0.000004904354526" ixz="0.003907344591" iyy="0.1401583096" iyz="0.00001817130601" izz="0.1060310134"/>
    </inertial>
  </link>
  <joint name="left_front_brake_joint" type="fixed">
    <parent link="body"/>
    <child link="arm_fl"/>
    <origin rpy="3.141592653589793 0 4.71238898038469" xyz="0.4031 0.353 0.1295"/>
  </joint>
  <link name="arm_fr">
    <visual>
      <origin rpy="3.141592653589793 0 1.5707963267948966" xyz="0 0 0"/>
      <geometry>
        <mesh filename="package://ocs2_robotic_assets/resources/mobile_manipulator/kortex/meshes/arm_fr.stl" scale="0.001 0.001 0.001"/>
      </geometry>
      <material name="white"/>
    </visual>
    <collision>
      <origin rpy="3.141592653589793 0 1.5707963267948966" xyz="0.0 0.232 0.130"/>
      <geometry>
        <box size="0.464 0.090 0.280"/>
      </geometry>
    </collision>
    <inertial>
      <mass value="4.680353119"/>
      <origin xyz="0.2874248231 0.000025732551 -0.1327515781"/>
      <inertia ixx="0.03793414031" ixy="-0.000004904354526" ixz="0.003907344591" iyy="0.1401583096" iyz="0.00001817130601" izz="0.1060310134"/>
    </inertial>
  </link>
  <joint name="right_front_brake_joint" type="fixed">
    <parent link="body"/>
    <child link="arm_fr"/>
    <origin rpy="3.141592653589793 0 1.5707963267948966" xyz="0.4031 -0.353 0.1290"/>
  </joint>
  <link name="leg_fl">
    <visual>
      <origin rpy="3.141592653589793 0 3.141592653589793" xyz="0 0 0"/>
      <geometry>
        <mesh filename="package://ocs2_robotic_assets/resources/mobile_manipulator/kortex/meshes/leg_fl.stl" scale="0.001 0.001 0.001"/>
      </geometry>
      <material name="white"/>
    </visual>
    <collision>
      <origin rpy="3.141592653589793 0 0" xyz="0 -0.045 0.166"/>
      <geometry>
        <box size="0.094 0.14 0.322"/>
      </geometry>
    </collision>
    <inertial>
      <mass value="2.953355758"/>
      <origin xyz="0.000025765612 -0.04067071313 -0.2120849525"/>
      <inertia ixx="0.02759751053" ixy="-0.000002760620178" ixz="-0.00000149396864" iyy="0.02582483119" iyz="0.006233490582" izz="0.005391981492"/>
    </inertial>
  </link>
  <joint name="left_front_steer_joint" type="revolute">
    <parent link="arm_fl"/>
    <child link="leg_fl"/>
    <origin rpy="0 0 1.5707963267948966" xyz="0 -0.4181 0.1244"/>
    <axis xyz="0 0 1"/>
    <limit effort="20.0" lower="-3.141" upper="3.141" velocity="0.5"/>
    <safety_controller k_position="100" k_velocity="100" soft_lower_limit="-3.0" soft_upper_limit="3.0"/>
    <joint_properties damping="1.0" friction="5.0"/>
  </joint>
  <transmission name="leg_fl_trans">
    <type>transmission_interface/SimpleTransmission</type>
    <actuator name="$leg_fl_steering">
      <mechanicalReduction>1</mechanicalReduction>
    </actuator>
    <joint name="left_front_steer_joint">
      <hardwareInterface>hardware_interface/PositionJointInterface</hardwareInterface>
    </joint>
  </transmission>
  <link name="leg_fr">
    <visual>
      <origin rpy="3.141592653589793 0 3.141592653589793" xyz="0 0 0"/>
      <geometry>
        <mesh filename="package://ocs2_robotic_assets/resources/mobile_manipulator/kortex/meshes/leg_fr.stl" scale="0.001 0.001 0.001"/>
      </geometry>
      <material name="white"/>
    </visual>
    <collision>
      <origin rpy="0 0 0" xyz="0 0.045 0.166"/>
      <geometry>
        <box size="0.094 0.14 0.322"/>
      </geometry>
    </collision>
    <inertial>
      <mass value="2.953355758"/>
      <origin xyz="0.000025765612 0.04067071313 -0.2120849525"/>
      <inertia ixx="0.02759751053" ixy="0.000002760620178" ixz="-0.00000149396864" iyy="0.02582483119" iyz="0.006233490582" izz="0.005391981492"/>
    </inertial>
  </link>
  <joint name="right_front_steer_joint" type="revolute">
    <parent link="arm_fr"/>
    <child link="leg_fr"/>
    <origin rpy="0 0 4.71238898038469" xyz="0 0.4181 0.1244"/>
    <axis xyz="0 0 1"/>
    <limit effort="20.0" lower="-3.141" upper="3.141" velocity="0.5"/>
    <safety_controller k_position="100" k_velocity="100" soft_lower_limit="-3.0" soft_upper_limit="3.0"/>
    <joint_properties damping="1.0" friction="5.0"/>
  </joint>
  <transmission name="leg_fr_trans">
    <type>transmission_interface/SimpleTransmission</type>
    <actuator name="$leg_fr_steering">
      <mechanicalReduction>1</mechanicalReduction>
    </actuator>
    <joint name="right_front_steer_joint">
      <hardwareInterface>hardware_interface/PositionJointInterface</hardwareInterface>
    </joint>
  </transmission>
  <link name="leg_rl">
    <visual>
      <origin rpy="3.141592653589793 0 0" xyz="0 0 0"/>
      <geometry>
        <mesh filename="package://ocs2_robotic_assets/resources/mobile_manipulator/kortex/meshes/leg_rl.stl" scale="0.001 0.001 0.001"/>
      </geometry>
      <material name="white"/>
    </visual>
    <collision>
      <origin rpy="3.141592653589793 0 0" xyz="0 0.045 0.166"/>
      <geometry>
        <box size="0.094 0.14 0.322"/>
      </geometry>
    </collision>
    <inertial>
      <mass value="2.953355758"/>
      <origin xyz="-0.000025765612 -0.04067071313 -0.2120849525"/>
      <inertia ixx="0.02759751053" ixy="-0.000002760620178" ixz="0.00000149396864" iyy="0.02582483119" iyz="-0.006233490582" izz="0.005391981492"/>
    </inertial>
  </link>
  <joint name="left_back_steer_joint" type="revolute">
    <parent link="arm_rl"/>
    <child link="leg_rl"/>
    <origin rpy="0 0 4.71238898038469" xyz="0 0.4181 0.1244"/>
    <axis xyz="0 0 1"/>
    <limit effort="20.0" lower="-3.141" upper="3.141" velocity="0.5"/>
    <safety_controller k_position="100" k_velocity="100" soft_lower_limit="-3.0" soft_upper_limit="3.0"/>
    <joint_properties damping="1.0" friction="5.0"/>
  </joint>
  <transmission name="leg_rl_trans">
    <type>transmission_interface/SimpleTransmission</type>
    <actuator name="$leg_rl_steering">
      <mechanicalReduction>1</mechanicalReduction>
    </actuator>
    <joint name="left_back_steer_joint">
      <hardwareInterface>hardware_interface/PositionJointInterface</hardwareInterface>
    </joint>
  </transmission>
  <link name="leg_rr">
    <visual>
      <origin rpy="0 3.141592653589793 3.141592653589793" xyz="0 0 0"/>
      <geometry>
        <mesh filename="package://ocs2_robotic_assets/resources/mobile_manipulator/kortex/meshes/leg_rr.stl" scale="0.001 0.001 0.001"/>
      </geometry>
      <material name="white"/>
    </visual>
    <collision>
      <origin rpy="0 3.141592653589793 3.141592653589793" xyz="0 -0.045 0.166"/>
      <geometry>
        <box size="0.094 0.14 0.322"/>
      </geometry>
    </collision>
    <inertial>
      <mass value="2.953355758"/>
      <origin xyz="-0.000025765612 0.04067071313 -0.2120849525"/>
      <inertia ixx="0.02759751053" ixy="0.000002760620178" ixz="0.00000149396864" iyy="0.02582483119" iyz="-0.006233490582" izz="0.005391981492"/>
    </inertial>
  </link>
  <joint name="right_back_steer_joint" type="revolute">
    <parent link="arm_rr"/>
    <child link="leg_rr"/>
    <origin rpy="0 0 1.5707963267948966" xyz="0 -0.4181 0.1244"/>
    <axis xyz="0 0 1"/>
    <limit effort="20.0" lower="-3.141" upper="3.141" velocity="0.5"/>
    <safety_controller k_position="100" k_velocity="100" soft_lower_limit="-3.0" soft_upper_limit="3.0"/>
    <joint_properties damping="1.0" friction="5.0"/>
  </joint>
  <transmission name="leg_rr_trans">
    <type>transmission_interface/SimpleTransmission</type>
    <actuator name="$leg_rr_steering">
      <mechanicalReduction>1</mechanicalReduction>
    </actuator>
    <joint name="right_back_steer_joint">
      <hardwareInterface>hardware_interface/PositionJointInterface</hardwareInterface>
    </joint>
  </transmission>
  <link name="wheel_fl">
    <visual>
      <origin rpy="1.5707963267948966 0 0" xyz="0 0 0"/>
      <geometry>
        <mesh filename="package://ocs2_robotic_assets/resources/mobile_manipulator/kortex/meshes/wheel_fl.stl" scale="0.001 0.001 0.001"/>
      </geometry>
      <material name="black"/>
    </visual>
    <collision>
      <origin rpy="3.141592653589793 0 0" xyz="0 -0.003 0"/>
      <geometry>
        <cylinder length="0.01" radius="0.100"/>
      </geometry>
    </collision>
    <inertial>
      <mass value="1.434561237"/>
      <origin xyz="0 -0.003225753823 0"/>
      <inertia ixx="0.003762436739" ixy="0" ixz="0" iyy="0.007084970164" iyz="0" izz="0.003762596989"/>
    </inertial>
  </link>
  <joint name="left_front_wheel_joint" type="revolute">
    <parent link="leg_fl"/>
    <child link="wheel_fl"/>
    <origin rpy="4.71238898038469 1.5707963267948966 0" xyz="0 0.0014 0.2746"/>
    <axis xyz="0 0 1"/>
    <limit effort="1000" velocity="5.0" lower="-300" upper="300"/>
    <safety_controller k_position="100" k_velocity="100"/>
    <joint_properties damping="1.0" friction="5.0"/>
  </joint>
  <transmission name="wheel_fl_trans">
    <type>transmission_interface/SimpleTransmission</type>
    <actuator name="wheel_fl_drive">
      <mechanicalReduction>1</mechanicalReduction>
    </actuator>
    <joint name="left_front_wheel_joint">
      <hardwareInterface>hardware_interface/VelocityJointInterface</hardwareInterface>
    </joint>
  </transmission>
  <gazebo reference="wheel_fl">
    <mu1 value="0.7"/>
    <mu2 value="0.5"/>
    <kp value="300000.0"/>
    <kd value="600.0"/>
  </gazebo>
  <link name="wheel_fr">
    <visual>
      <origin rpy="-1.5707963267948966 0 0" xyz="0 0 0"/>
      <geometry>
        <mesh filename="package://ocs2_robotic_assets/resources/mobile_manipulator/kortex/meshes/wheel_fr.stl" scale="0.001 0.001 0.001"/>
      </geometry>
      <material name="black"/>
    </visual>
    <collision>
      <origin rpy="3.141592653589793 0 0" xyz="0 0.003 0"/>
      <geometry>
        <cylinder length="0.01" radius="0.100"/>
      </geometry>
    </collision>
    <inertial>
      <mass value="1.434561237"/>
      <origin xyz="0 0.003225753823 0"/>
      <inertia ixx="0.003762436739" ixy="0" ixz="0" iyy="0.007084970164" iyz="0" izz="0.003762596989"/>
    </inertial>
  </link>
  <joint name="right_front_wheel_joint" type="revolute">
    <parent link="leg_fr"/>
    <child link="wheel_fr"/>
    <origin rpy="1.5707963267948966 1.5707963267948966 0" xyz="0 -0.0013 0.2746"/>
    <axis xyz="0 0 1"/>
    <limit effort="1000" velocity="5.0" lower="-300" upper="300"/>
    <safety_controller k_position="100" k_velocity="100"/>
    <joint_properties damping="1.0" friction="5.0"/>
  </joint>
  <transmission name="wheel_fr_trans">
    <type>transmission_interface/SimpleTransmission</type>
    <actuator name="wheel_fr_drive">
      <mechanicalReduction>1</mechanicalReduction>
    </actuator>
    <joint name="right_front_wheel_joint">
      <hardwareInterface>hardware_interface/VelocityJointInterface</hardwareInterface>
    </joint>
  </transmission>
  <gazebo reference="wheel_fr">
    <mu1 value="0.7"/>
    <mu2 value="0.5"/>
    <kp value="300000.0"/>
    <kd value="600.0"/>
  </gazebo>
  <link name="wheel_rl">
    <visual>
      <origin rpy="1.5707963267948966 0 0" xyz="0 0 0"/>
      <geometry>
        <mesh filename="package://ocs2_robotic_assets/resources/mobile_manipulator/kortex/meshes/wheel_rl.stl" scale="0.001 0.001 0.001"/>
      </geometry>
      <material name="black"/>
    </visual>
    <collision>
      <origin rpy="3.141592653589793 0 0" xyz="0 0.003 0"/>
      <geometry>
        <cylinder length="0.01" radius="0.100"/>
      </geometry>
    </collision>
    <inertial>
      <mass value="1.434561237"/>
      <origin xyz="0 -0.003225753823 0"/>
      <inertia ixx="0.003762436739" ixy="0" ixz="0" iyy="0.007084970164" iyz="0" izz="0.003762596989"/>
    </inertial>
  </link>
  <joint name="left_back_wheel_joint" type="revolute">
    <parent link="leg_rl"/>
    <child link="wheel_rl"/>
    <origin rpy="1.5707963267948966 1.5707963267948966 0" xyz="0 -0.0013 0.2746"/>
    <axis xyz="0 0 1"/>
    <limit effort="1000" velocity="5.0" lower="-300" upper="300"/>
    <safety_controller k_position="100" k_velocity="100"/>
    <joint_properties damping="1.0" friction="5.0"/>
  </joint>
  <transmission name="wheel_rl_trans">
    <type>transmission_interface/SimpleTransmission</type>
    <actuator name="wheel_rl_drive">
      <mechanicalReduction>1</mechanicalReduction>
    </actuator>
    <joint name="left_back_wheel_joint">
      <hardwareInterface>hardware_interface/VelocityJointInterface</hardwareInterface>
    </joint>
  </transmission>
  <gazebo reference="wheel_rl">
    <mu1 value="0.7"/>
    <mu2 value="0.5"/>
    <kp value="300000.0"/>
    <kd value="600.0"/>
  </gazebo>
  <link name="wheel_rr">
    <visual>
      <origin rpy="4.71238898038469 0 0" xyz="0 0 0"/>
      <geometry>
        <mesh filename="package://ocs2_robotic_assets/resources/mobile_manipulator/kortex/meshes/wheel_rr.stl" scale="0.001 0.001 0.001"/>
      </geometry>
      <material name="black"/>
    </visual>
    <collision>
      <origin rpy="3.141592653589793 0 0" xyz="0 0.003 0"/>
      <geometry>
        <cylinder length="0.01" radius="0.100"/>
      </geometry>
    </collision>
    <inertial>
      <mass value="1.434561237"/>
      <origin xyz="0 0.003225753823 0"/>
      <inertia ixx="0.003762436739" ixy="0" ixz="0" iyy="0.007084970164" iyz="0" izz="0.003762596989"/>
    </inertial>
  </link>
  <joint name="right_back_wheel_joint" type="revolute">
    <parent link="leg_rr"/>
    <child link="wheel_rr"/>
    <origin rpy="4.71238898038469 1.5707963267948966 0" xyz="0 -0.0014 0.2746"/>
    <axis xyz="0 0 1"/>
    <limit effort="1000" velocity="5.0" lower="-300" upper="300"/>
    <safety_controller k_position="100" k_velocity="100"/>
    <joint_properties damping="1.0" friction="5.0"/>
  </joint>
  <transmission name="wheel_rr_trans">
    <type>transmission_interface/SimpleTransmission</type>
    <actuator name="wheel_rr_drive">
      <mechanicalReduction>1</mechanicalReduction>
    </actuator>
    <joint name="right_back_wheel_joint">
      <hardwareInterface>hardware_interface/VelocityJointInterface</hardwareInterface>
    </joint>
  </transmission>
  <gazebo reference="wheel_rr">
    <mu1 value="0.7"/>
    <mu2 value="0.5"/>
    <kp value="300000.0"/>
    <kd value="600.0"/>
  </gazebo>
  <gazebo>
    <plugin filename="libgazebo_ros_control.so" name="gazebo_ros_control">
      <robotNamespace>/swerve</robotNamespace>
    </plugin>
  </gazebo>
  <!-- Attach base to arm -->
  <joint name="base_to_arm_joint" type="fixed">
    <origin rpy="0 0 0" xyz="0 0 0"/>
    <parent link="mabi_attachment"/>
    <child link="base_link"/>
  </joint>
  <!-- Robot arm -->
  <link name="base_link">
    <inertial>
      <origin rpy="0 0 0" xyz="-0.000648 -0.000166 0.084487"/>
      <mass value="1.697"/>
      <inertia ixx="0.004622" ixy="9E-06" ixz="6E-05" iyy="0.004495" iyz="9E-06" izz="0.002079"/>
    </inertial>
    <visual>
      <origin rpy="0 0 0" xyz="0 0 0"/>
      <geometry>
        <mesh filename="package://ocs2_robotic_assets/resources/mobile_manipulator/kortex/meshes/base_link.STL"/>
      </geometry>
      <material name="">
        <color rgba="0.75294 0.75294 0.75294 1"/>
      </material>
    </visual>
    <collision>
      <origin rpy="0 0 0" xyz="0 0 0"/>
      <geometry>
        <mesh filename="package://ocs2_robotic_assets/resources/mobile_manipulator/kortex/meshes/base_link.STL"/>
      </geometry>
    </collision>
  </link>
  <link name="shoulder_link">
    <inertial>
      <origin rpy="0 0 0" xyz="-2.3E-05 -0.010364 -0.07336"/>
      <mass value="1.3773"/>
      <inertia ixx="0.00457" ixy="1E-06" ixz="2E-06" iyy="0.004831" iyz="0.000448" izz="0.001409"/>
    </inertial>
    <visual>
      <origin rpy="0 0 0" xyz="0 0 0"/>
      <geometry>
        <mesh filename="package://ocs2_robotic_assets/resources/mobile_manipulator/kortex/meshes/shoulder_link.STL"/>
      </geometry>
      <material name="">
        <color rgba="0.75294 0.75294 0.75294 1"/>
      </material>
    </visual>
    <collision>
      <origin rpy="0 0 0" xyz="0 0 0"/>
      <geometry>
        <mesh filename="package://ocs2_robotic_assets/resources/mobile_manipulator/kortex/meshes/shoulder_link.STL"/>
      </geometry>
    </collision>
  </link>
  <joint name="joint_1" type="revolute">
    <origin rpy="3.1416 2.7629E-18 -4.9305E-36" xyz="0 0 0.15643"/>
    <parent link="base_link"/>
    <child link="shoulder_link"/>
    <axis xyz="0 0 1"/>
    <limit effort="39" velocity="1.05" lower="-300" upper="300"/>
  </joint>
  <link name="half_arm_1_link">
    <inertial>
      <origin rpy="0 0 0" xyz="-4.4E-05 -0.09958 -0.013278"/>
      <mass value="1.1636"/>
      <inertia ixx="0.011088" ixy="5E-06" ixz="0" iyy="0.001072" iyz="-0.000691" izz="0.011255"/>
    </inertial>
    <visual>
      <origin rpy="0 0 0" xyz="0 0 0"/>
      <geometry>
        <mesh filename="package://ocs2_robotic_assets/resources/mobile_manipulator/kortex/meshes/half_arm_1_link.STL"/>
      </geometry>
      <material name="">
        <color rgba="0.75294 0.75294 0.75294 1"/>
      </material>
    </visual>
    <collision>
      <origin rpy="0 0 0" xyz="0 0 0"/>
      <geometry>
        <mesh filename="package://ocs2_robotic_assets/resources/mobile_manipulator/kortex/meshes/half_arm_1_link.STL"/>
      </geometry>
    </collision>
  </link>
  <joint name="joint_2" type="revolute">
    <origin rpy="1.5708 2.1343E-17 -1.1102E-16" xyz="0 0.005375 -0.12838"/>
    <parent link="shoulder_link"/>
    <child link="half_arm_1_link"/>
    <axis xyz="0 0 1"/>
    <limit effort="39" lower="-2.24" upper="2.24" velocity="1.05"/>
  </joint>
  <link name="half_arm_2_link">
    <inertial>
      <origin rpy="0 0 0" xyz="-4.4E-05 -0.006641 -0.117892"/>
      <mass value="1.1636"/>
      <inertia ixx="0.010932" ixy="0" ixz="-7E-06" iyy="0.011127" iyz="0.000606" izz="0.001043"/>
    </inertial>
    <visual>
      <origin rpy="0 0 0" xyz="0 0 0"/>
      <geometry>
        <mesh filename="package://ocs2_robotic_assets/resources/mobile_manipulator/kortex/meshes/half_arm_2_link.STL"/>
      </geometry>
      <material name="">
        <color rgba="0.75294 0.75294 0.75294 1"/>
      </material>
    </visual>
    <collision>
      <origin rpy="0 0 0" xyz="0 0 0"/>
      <geometry>
        <mesh filename="package://ocs2_robotic_assets/resources/mobile_manipulator/kortex/meshes/half_arm_2_link.STL"/>
      </geometry>
    </collision>
  </link>
  <joint name="joint_3" type="revolute">
    <origin rpy="-1.5708 1.2326E-32 -2.9122E-16" xyz="0 -0.21038 -0.006375"/>
    <parent link="half_arm_1_link"/>
    <child link="half_arm_2_link"/>
    <axis xyz="0 0 1"/>
    <limit effort="39" velocity="1.05" lower="-300" upper="300"/>
  </joint>
  <link name="forearm_link">
    <inertial>
      <origin rpy="0 0 0" xyz="-1.8E-05 -0.075478 -0.015006"/>
      <mass value="0.9302"/>
      <inertia ixx="0.008147" ixy="-1E-06" ixz="0" iyy="0.000631" iyz="-0.0005" izz="0.008316"/>
    </inertial>
    <visual>
      <origin rpy="0 0 0" xyz="0 0 0"/>
      <geometry>
        <mesh filename="package://ocs2_robotic_assets/resources/mobile_manipulator/kortex/meshes/forearm_link.STL"/>
      </geometry>
      <material name="">
        <color rgba="0.75294 0.75294 0.75294 1"/>
      </material>
    </visual>
    <collision>
      <origin rpy="0 0 0" xyz="0 0 0"/>
      <geometry>
        <mesh filename="package://ocs2_robotic_assets/resources/mobile_manipulator/kortex/meshes/forearm_link.STL"/>
      </geometry>
    </collision>
  </link>
  <joint name="joint_4" type="revolute">
    <origin rpy="1.5708 -6.6954E-17 -1.6653E-16" xyz="0 0.006375 -0.21038"/>
    <parent link="half_arm_2_link"/>
    <child link="forearm_link"/>
    <axis xyz="0 0 1"/>
    <limit effort="39" lower="-2.57" upper="2.57" velocity="1.05"/>
  </joint>
  <link name="spherical_wrist_1_link">
    <inertial>
      <origin rpy="0 0 0" xyz="1E-06 -0.009432 -0.063883"/>
      <mass value="0.6781"/>
      <inertia ixx="0.001596" ixy="0" ixz="0" iyy="0.001607" iyz="0.000256" izz="0.000399"/>
    </inertial>
    <visual>
      <origin rpy="0 0 0" xyz="0 0 0"/>
      <geometry>
        <mesh filename="package://ocs2_robotic_assets/resources/mobile_manipulator/kortex/meshes/spherical_wrist_1_link.STL"/>
      </geometry>
      <material name="">
        <color rgba="0.75294 0.75294 0.75294 1"/>
      </material>
    </visual>
    <collision>
      <origin rpy="0 0 0" xyz="0 0 0"/>
      <geometry>
        <mesh filename="package://ocs2_robotic_assets/resources/mobile_manipulator/kortex/meshes/spherical_wrist_1_link.STL"/>
      </geometry>
    </collision>
  </link>
  <joint name="joint_5" type="revolute">
    <origin rpy="-1.5708 2.2204E-16 -6.373E-17" xyz="0 -0.20843 -0.006375"/>
    <parent link="forearm_link"/>
    <child link="spherical_wrist_1_link"/>
    <axis xyz="0 0 1"/>
    <limit effort="9" velocity="1.05" lower="-300" upper="300"/>
  </joint>
  <link name="spherical_wrist_2_link">
    <inertial>
      <origin rpy="0 0 0" xyz="1E-06 -0.045483 -0.00965"/>
      <mass value="0.6781"/>
      <inertia ixx="0.001641" ixy="0" ixz="0" iyy="0.00041" iyz="-0.000278" izz="0.001641"/>
    </inertial>
    <visual>
      <origin rpy="0 0 0" xyz="0 0 0"/>
      <geometry>
        <mesh filename="package://ocs2_robotic_assets/resources/mobile_manipulator/kortex/meshes/spherical_wrist_2_link.STL"/>
      </geometry>
      <material name="">
        <color rgba="0.75294 0.75294 0.75294 1"/>
      </material>
    </visual>
    <collision>
      <origin rpy="0 0 0" xyz="0 0 0"/>
      <geometry>
        <mesh filename="package://ocs2_robotic_assets/resources/mobile_manipulator/kortex/meshes/spherical_wrist_2_link.STL"/>
      </geometry>
    </collision>
  </link>
  <joint name="joint_6" type="revolute">
    <origin rpy="1.5708 9.2076E-28 -8.2157E-15" xyz="0 0.00017505 -0.10593"/>
    <parent link="spherical_wrist_1_link"/>
    <child link="spherical_wrist_2_link"/>
    <axis xyz="0 0 1"/>
    <limit effort="9" lower="-2.09" upper="2.09" velocity="1.05"/>
  </joint>
  <link name="bracelet_link">
    <inertial>
      <origin rpy="0 0 0" xyz="0.000281 0.011402 -0.029798"/>
      <mass value="0.5"/>
      <inertia ixx="0.000587" ixy="3E-06" ixz="3E-06" iyy="0.000369" iyz="-0.000118" izz="0.000609"/>
    </inertial>
    <visual>
      <origin rpy="0 0 0" xyz="0 0 0"/>
      <geometry>
        <mesh filename="package://ocs2_robotic_assets/resources/mobile_manipulator/kortex/meshes/bracelet_with_vision_link.STL"/>
      </geometry>
      <material name="">
        <color rgba="0.75294 0.75294 0.75294 1"/>
      </material>
    </visual>
    <collision>
      <origin rpy="0 0 0" xyz="0 0 0"/>
      <geometry>
        <mesh filename="package://ocs2_robotic_assets/resources/mobile_manipulator/kortex/meshes/bracelet_with_vision_link.STL"/>
      </geometry>
    </collision>
  </link>
  <joint name="joint_7" type="revolute">
    <origin rpy="-1.5708 -5.5511E-17 9.6396E-17" xyz="0 -0.10593 -0.00017505"/>
    <parent link="spherical_wrist_2_link"/>
    <child link="bracelet_link"/>
    <axis xyz="0 0 1"/>
    <limit effort="9" velocity="1.05" lower="-300" upper="300"/>
  </joint>
  <link name="end_effector_link"/>
  <joint name="end_effector" type="fixed">
    <origin rpy="3.14159265358979 1.09937075168372E-32 0" xyz="0 0 -0.0615250000000001"/>
    <parent link="bracelet_link"/>
    <child link="end_effector_link"/>
    <axis xyz="0 0 0"/>
  </joint>
  <link name="camera_link"/>
  <joint name="camera_module" type="fixed">
    <origin rpy="3.14159265358979 3.14159265358979 0" xyz="0 0.05639 -0.00305"/>
    <parent link="end_effector_link"/>
    <child link="camera_link"/>
  </joint>
  <link name="camera_depth_frame"/>
  <joint name="depth_module" type="fixed">
    <origin rpy="3.14159265358979 3.14159265358979 0" xyz="0.0275 0.066 -0.00305"/>
    <parent link="end_effector_link"/>
    <child link="camera_depth_frame"/>
  </joint>
  <link name="camera_color_frame"/>
  <joint name="color_module" type="fixed">
    <origin rpy="3.14159265358979 3.14159265358979 0" xyz="0 0.05639 -0.00305"/>
    <parent link="end_effector_link"/>
    <child link="camera_color_frame"/>
  </joint>
  <!-- This line was removed by Kinova because we replaced the transmission file with our own 
    <xacro:include filename="$(find robotiq_2f_85_gripper_visualization)/urdf/robotiq_arg2f_transmission.xacro" /> -->
  <!-- Tool frame used by the arm -->
  <link name="tool_frame"/>
  <joint name="tool_frame_joint" type="fixed">
    <origin rpy="0 0 0" xyz="0 0 0.120"/>
    <parent link="end_effector_link"/>
    <child link="tool_frame"/>
    <axis xyz="0 0 0"/>
  </joint>
  <!-- This joint was added by Kinova -->
  <joint name="gripper_base_joint" type="fixed">
    <parent link="end_effector_link"/>
    <child link="robotiq_arg2f_base_link"/>
    <origin rpy="0.0 0.0 1.57" xyz="0.0 0.0 0.0"/>
  </joint>
  <link name="robotiq_arg2f_base_link">
    <inertial>
      <origin rpy="0 0 0" xyz="8.625E-08 -4.6583E-06 0.03145"/>
      <mass value="0.22652"/>
      <inertia ixx="0.00020005" ixy="-4.2442E-10" ixz="-2.9069E-10" iyy="0.00017832" iyz="-3.4402E-08" izz="0.00013478"/>
    </inertial>
    <visual>
      <origin rpy="0 0 0" xyz="0 0 0"/>
      <geometry>
        <!-- The DAE file doesn't show well in Gazebo so we're using the STL instead -->
        <!-- <mesh filename="package://ocs2_robotic_assets/resources/mobile_manipulator/kortex/meshes/visual/robotiq_arg2f_85_base_link.dae" scale="0.001 0.001 0.001"/> -->
        <mesh filename="package://ocs2_robotic_assets/resources/mobile_manipulator/kortex/meshes/collision/robotiq_arg2f_base_link.stl"/>
      </geometry>
      <material name="">
        <color rgba="0.1 0.1 0.1 1"/>
      </material>
    </visual>
    <collision>
      <origin rpy="0 0 0" xyz="0 0 0"/>
      <geometry>
        <mesh filename="package://ocs2_robotic_assets/resources/mobile_manipulator/kortex/meshes/collision/robotiq_arg2f_base_link.stl"/>
      </geometry>
    </collision>
  </link>
  <gazebo reference="robotiq_arg2f_base_link">
    <material>Gazebo/Black</material>
  </gazebo>
  <link name="left_outer_knuckle">
    <inertial>
      <origin rpy="0 0 0" xyz="-0.000200000000003065 0.0199435877845359 0.0292245259211331"/>
      <mass value="0.00853198276973456"/>
      <inertia ixx="2.89328108496468E-06" ixy="-1.57935047237397E-19" ixz="-1.93980378593255E-19" iyy="1.86719750325683E-06" iyz="-1.21858577871576E-06" izz="1.21905238907251E-06"/>
    </inertial>
    <visual>
      <origin rpy="0 0 0" xyz="0 0 0"/>
      <geometry>
        <mesh filename="package://ocs2_robotic_assets/resources/mobile_manipulator/kortex/meshes/visual/robotiq_arg2f_85_outer_knuckle.dae" scale="0.001 0.001 0.001"/>
      </geometry>
      <material name="">
        <color rgba="0.792156862745098 0.819607843137255 0.933333333333333 1"/>
      </material>
    </visual>
    <collision>
      <origin rpy="0 0 0" xyz="0 0 0"/>
      <geometry>
        <mesh filename="package://ocs2_robotic_assets/resources/mobile_manipulator/kortex/meshes/collision/robotiq_arg2f_85_outer_knuckle.dae" scale="0.001 0.001 0.001"/>
      </geometry>
    </collision>
  </link>
  <link name="left_outer_finger">
    <inertial>
      <origin rpy="0 0 0" xyz="0.00030115855001899 0.0373907951953854 -0.0208027427000385"/>
      <mass value="0.022614240507152"/>
      <inertia ixx="1.52518312458174E-05" ixy="9.76583423954399E-10" ixz="-5.43838577022588E-10" iyy="6.17694243867776E-06" iyz="6.78636130740228E-06" izz="1.16494917907219E-05"/>
    </inertial>
    <visual>
      <origin rpy="0 0 0" xyz="0 0 0"/>
      <geometry>
        <mesh filename="package://ocs2_robotic_assets/resources/mobile_manipulator/kortex/meshes/visual/robotiq_arg2f_85_outer_finger.dae" scale="0.001 0.001 0.001"/>
      </geometry>
      <material name="">
        <color rgba="0.1 0.1 0.1 1"/>
      </material>
    </visual>
    <collision>
      <origin rpy="0 0 0" xyz="0 0 0"/>
      <geometry>
        <mesh filename="package://ocs2_robotic_assets/resources/mobile_manipulator/kortex/meshes/collision/robotiq_arg2f_85_outer_finger.dae" scale="0.001 0.001 0.001"/>
      </geometry>
    </collision>
  </link>
  <link name="left_inner_finger">
    <inertial>
      <origin rpy="0 0 0" xyz="0.000299999999999317 0.0160078233491243 -0.0136945669206257"/>
      <mass value="0.0104003125914103"/>
      <inertia ixx="2.71909453810972E-06" ixy="1.35402465472579E-21" ixz="-7.1817349065269E-22" iyy="7.69100314106116E-07" iyz="6.74715432769696E-07" izz="2.30315190420171E-06"/>
    </inertial>
    <visual>
      <origin rpy="0 0 0" xyz="0 0 0"/>
      <geometry>
        <mesh filename="package://ocs2_robotic_assets/resources/mobile_manipulator/kortex/meshes/visual/robotiq_arg2f_85_inner_finger.dae" scale="0.001 0.001 0.001"/>
      </geometry>
      <material name="">
        <color rgba="0.1 0.1 0.1 1"/>
      </material>
    </visual>
    <collision>
      <origin rpy="0 0 0" xyz="0 0 0"/>
      <geometry>
        <mesh filename="package://ocs2_robotic_assets/resources/mobile_manipulator/kortex/meshes/collision/robotiq_arg2f_85_inner_finger.dae" scale="0.001 0.001 0.001"/>
      </geometry>
    </collision>
  </link>
  <link name="left_inner_finger_pad">
    <visual>
      <origin rpy="0 0 0" xyz="0 0 0"/>
      <geometry>
        <box size="0.022 0.00635 0.0375"/>
      </geometry>
      <material name="">
        <color rgba="0.9 0.9 0.9 1"/>
      </material>
    </visual>
    <collision>
      <origin rpy="0 0 0" xyz="0 0 0"/>
      <geometry>
        <box size="0.022 0.00635 0.0375"/>
      </geometry>
      <material name="">
        <color rgba="0.9 0.0 0.0 1"/>
      </material>
    </collision>
  </link>
  <link name="left_inner_knuckle">
    <inertial>
      <origin rpy="0 0 0" xyz="0.000123011831763771 0.0507850843201817 0.00103968640075166"/>
      <mass value="0.0271177346495152"/>
      <inertia ixx="2.61910379223783E-05" ixy="-2.43616858946494E-07" ixz="-6.37789906117123E-09" iyy="2.8270243746167E-06" iyz="-5.37200748039765E-07" izz="2.83695868220296E-05"/>
    </inertial>
    <visual>
      <origin rpy="0 0 0" xyz="0 0 0"/>
      <geometry>
        <mesh filename="package://ocs2_robotic_assets/resources/mobile_manipulator/kortex/meshes/visual/robotiq_arg2f_85_inner_knuckle.dae" scale="0.001 0.001 0.001"/>
      </geometry>
      <material name="">
        <color rgba="0.1 0.1 0.1 1"/>
      </material>
    </visual>
    <collision>
      <origin rpy="0 0 0" xyz="0 0 0"/>
      <geometry>
        <mesh filename="package://ocs2_robotic_assets/resources/mobile_manipulator/kortex/meshes/collision/robotiq_arg2f_85_inner_knuckle.dae" scale="0.001 0.001 0.001"/>
      </geometry>
    </collision>
  </link>
  <link name="right_outer_knuckle">
    <inertial>
      <origin rpy="0 0 0" xyz="-0.000200000000003065 0.0199435877845359 0.0292245259211331"/>
      <mass value="0.00853198276973456"/>
      <inertia ixx="2.89328108496468E-06" ixy="-1.57935047237397E-19" ixz="-1.93980378593255E-19" iyy="1.86719750325683E-06" iyz="-1.21858577871576E-06" izz="1.21905238907251E-06"/>
    </inertial>
    <visual>
      <origin rpy="0 0 0" xyz="0 0 0"/>
      <geometry>
        <mesh filename="package://ocs2_robotic_assets/resources/mobile_manipulator/kortex/meshes/visual/robotiq_arg2f_85_outer_knuckle.dae" scale="0.001 0.001 0.001"/>
      </geometry>
      <material name="">
        <color rgba="0.792156862745098 0.819607843137255 0.933333333333333 1"/>
      </material>
    </visual>
    <collision>
      <origin rpy="0 0 0" xyz="0 0 0"/>
      <geometry>
        <mesh filename="package://ocs2_robotic_assets/resources/mobile_manipulator/kortex/meshes/collision/robotiq_arg2f_85_outer_knuckle.dae" scale="0.001 0.001 0.001"/>
      </geometry>
    </collision>
  </link>
  <link name="right_outer_finger">
    <inertial>
      <origin rpy="0 0 0" xyz="0.00030115855001899 0.0373907951953854 -0.0208027427000385"/>
      <mass value="0.022614240507152"/>
      <inertia ixx="1.52518312458174E-05" ixy="9.76583423954399E-10" ixz="-5.43838577022588E-10" iyy="6.17694243867776E-06" iyz="6.78636130740228E-06" izz="1.16494917907219E-05"/>
    </inertial>
    <visual>
      <origin rpy="0 0 0" xyz="0 0 0"/>
      <geometry>
        <mesh filename="package://ocs2_robotic_assets/resources/mobile_manipulator/kortex/meshes/visual/robotiq_arg2f_85_outer_finger.dae" scale="0.001 0.001 0.001"/>
      </geometry>
      <material name="">
        <color rgba="0.1 0.1 0.1 1"/>
      </material>
    </visual>
    <collision>
      <origin rpy="0 0 0" xyz="0 0 0"/>
      <geometry>
        <mesh filename="package://ocs2_robotic_assets/resources/mobile_manipulator/kortex/meshes/collision/robotiq_arg2f_85_outer_finger.dae" scale="0.001 0.001 0.001"/>
      </geometry>
    </collision>
  </link>
  <link name="right_inner_finger">
    <inertial>
      <origin rpy="0 0 0" xyz="0.000299999999999317 0.0160078233491243 -0.0136945669206257"/>
      <mass value="0.0104003125914103"/>
      <inertia ixx="2.71909453810972E-06" ixy="1.35402465472579E-21" ixz="-7.1817349065269E-22" iyy="7.69100314106116E-07" iyz="6.74715432769696E-07" izz="2.30315190420171E-06"/>
    </inertial>
    <visual>
      <origin rpy="0 0 0" xyz="0 0 0"/>
      <geometry>
        <mesh filename="package://ocs2_robotic_assets/resources/mobile_manipulator/kortex/meshes/visual/robotiq_arg2f_85_inner_finger.dae" scale="0.001 0.001 0.001"/>
      </geometry>
      <material name="">
        <color rgba="0.1 0.1 0.1 1"/>
      </material>
    </visual>
    <collision>
      <origin rpy="0 0 0" xyz="0 0 0"/>
      <geometry>
        <mesh filename="package://ocs2_robotic_assets/resources/mobile_manipulator/kortex/meshes/collision/robotiq_arg2f_85_inner_finger.dae" scale="0.001 0.001 0.001"/>
      </geometry>
    </collision>
  </link>
  <link name="right_inner_finger_pad">
    <visual>
      <origin rpy="0 0 0" xyz="0 0 0"/>
      <geometry>
        <box size="0.022 0.00635 0.0375"/>
      </geometry>
      <material name="">
        <color rgba="0.9 0.9 0.9 1"/>
      </material>
    </visual>
    <collision>
      <origin rpy="0 0 0" xyz="0 0 0"/>
      <geometry>
        <box size="0.022 0.00635 0.0375"/>
      </geometry>
      <material name="">
        <color rgba="0.9 0.0 0.0 1"/>
      </material>
    </collision>
  </link>
  <link name="right_inner_knuckle">
    <inertial>
      <origin rpy="0 0 0" xyz="0.000123011831763771 0.0507850843201817 0.00103968640075166"/>
      <mass value="0.0271177346495152"/>
      <inertia ixx="2.61910379223783E-05" ixy="-2.43616858946494E-07" ixz="-6.37789906117123E-09" iyy="2.8270243746167E-06" iyz="-5.37200748039765E-07" izz="2.83695868220296E-05"/>
    </inertial>
    <visual>
      <origin rpy="0 0 0" xyz="0 0 0"/>
      <geometry>
        <mesh filename="package://ocs2_robotic_assets/resources/mobile_manipulator/kortex/meshes/visual/robotiq_arg2f_85_inner_knuckle.dae" scale="0.001 0.001 0.001"/>
      </geometry>
      <material name="">
        <color rgba="0.1 0.1 0.1 1"/>
      </material>
    </visual>
    <collision>
      <origin rpy="0 0 0" xyz="0 0 0"/>
      <geometry>
        <mesh filename="package://ocs2_robotic_assets/resources/mobile_manipulator/kortex/meshes/collision/robotiq_arg2f_85_inner_knuckle.dae" scale="0.001 0.001 0.001"/>
      </geometry>
    </collision>
  </link>
  <joint name="finger_joint" type="revolute">
    <origin rpy="0 0 3.141592653589793" xyz="0 -0.0306011 0.054904"/>
    <parent link="robotiq_arg2f_base_link"/>
    <child link="left_outer_knuckle"/>
    <axis xyz="1 0 0"/>
    <limit effort="1000" lower="0" upper="0.8" velocity="2.0"/>
  </joint>
  <joint name="left_outer_finger_joint" type="fixed">
    <origin rpy="0 0 0" xyz="0 0.0315 -0.0041"/>
    <parent link="left_outer_knuckle"/>
    <child link="left_outer_finger"/>
    <axis xyz="1 0 0"/>
  </joint>
  <joint name="left_inner_knuckle_joint" type="revolute">
    <!-- <origin xyz="0 ${reflect * -0.0127} 0.06142" rpy="${pi / 2 + .725} 0 ${(reflect - 1) * pi / 2}" /> -->
    <origin rpy="0 0 3.141592653589793" xyz="0 -0.0127 0.06142"/>
    <parent link="robotiq_arg2f_base_link"/>
    <child link="left_inner_knuckle"/>
    <axis xyz="1 0 0"/>
    <limit effort="1000" lower="0" upper="0.8757" velocity="2.0"/>
    <mimic joint="finger_joint" multiplier="1" offset="0"/>
  </joint>
  <joint name="left_inner_finger_joint" type="revolute">
    <origin rpy="0 0 0" xyz="0 0.0061 0.0471"/>
    <parent link="left_outer_finger"/>
    <child link="left_inner_finger"/>
    <axis xyz="1 0 0"/>
    <limit effort="1000" lower="-0.8757" upper="0.8757" velocity="2.0"/>
    <mimic joint="finger_joint" multiplier="-1" offset="0"/>
  </joint>
  <joint name="left_inner_finger_pad_joint" type="fixed">
    <origin rpy="0 0 0" xyz="0 -0.0220203446692936 0.03242"/>
    <parent link="left_inner_finger"/>
    <child link="left_inner_finger_pad"/>
    <axis xyz="0 0 1"/>
  </joint>
  <joint name="right_outer_knuckle_joint" type="revolute">
    <origin rpy="0 0 0" xyz="0 0.0306011 0.054904"/>
    <parent link="robotiq_arg2f_base_link"/>
    <child link="right_outer_knuckle"/>
    <axis xyz="1 0 0"/>
    <limit effort="1000" lower="0" upper="0.81" velocity="2.0"/>
    <mimic joint="finger_joint" multiplier="1" offset="0"/>
  </joint>
  <joint name="right_outer_finger_joint" type="fixed">
    <origin rpy="0 0 0" xyz="0 0.0315 -0.0041"/>
    <parent link="right_outer_knuckle"/>
    <child link="right_outer_finger"/>
    <axis xyz="1 0 0"/>
  </joint>
  <joint name="right_inner_knuckle_joint" type="revolute">
    <!-- <origin xyz="0 ${reflect * -0.0127} 0.06142" rpy="${pi / 2 + .725} 0 ${(reflect - 1) * pi / 2}" /> -->
    <origin rpy="0 0 0.0" xyz="0 0.0127 0.06142"/>
    <parent link="robotiq_arg2f_base_link"/>
    <child link="right_inner_knuckle"/>
    <axis xyz="1 0 0"/>
    <limit effort="1000" lower="0" upper="0.8757" velocity="2.0"/>
    <mimic joint="finger_joint" multiplier="1" offset="0"/>
  </joint>
  <joint name="right_inner_finger_joint" type="revolute">
    <origin rpy="0 0 0" xyz="0 0.0061 0.0471"/>
    <parent link="right_outer_finger"/>
    <child link="right_inner_finger"/>
    <axis xyz="1 0 0"/>
    <limit effort="1000" lower="-0.8757" upper="0.8757" velocity="2.0"/>
    <mimic joint="finger_joint" multiplier="-1" offset="0"/>
  </joint>
  <joint name="right_inner_finger_pad_joint" type="fixed">
    <origin rpy="0 0 0" xyz="0 -0.0220203446692936 0.03242"/>
    <parent link="right_inner_finger"/>
    <child link="right_inner_finger_pad"/>
    <axis xyz="0 0 1"/>
  </joint>
  <!-- Transmissions are loaded in the generic kortex xacro when simulation is enabled -->
  <!-- <xacro:robotiq_arg2f_transmission prefix="${prefix}"/> -->
</robot>
